:: loading settings :: url = jar:file:/opt/spark/jars/ivy-2.5.1.jar!/org/apache/ivy/core/settings/ivysettings.xml
ERROR:root:Exception while sending command.
Traceback (most recent call last):
  File "/opt/spark/python/lib/py4j-0.10.9.7-src.zip/py4j/clientserver.py", line 511, in send_command
    answer = smart_decode(self.stream.readline()[:-1])
RuntimeError: reentrant call inside <_io.BufferedReader name=3>

During handling of the above exception, another exception occurred:

Traceback (most recent call last):
  File "/opt/spark/python/lib/py4j-0.10.9.7-src.zip/py4j/java_gateway.py", line 1038, in send_command
    response = connection.send_command(command)
  File "/opt/spark/python/lib/py4j-0.10.9.7-src.zip/py4j/clientserver.py", line 539, in send_command
    raise Py4JNetworkError(
py4j.protocol.Py4JNetworkError: Error while sending or receiving
ERROR:root:Exception while sending command.
Traceback (most recent call last):
  File "/opt/spark/python/lib/py4j-0.10.9.7-src.zip/py4j/clientserver.py", line 511, in send_command
    answer = smart_decode(self.stream.readline()[:-1])
  File "/usr/lib/python3.10/socket.py", line 705, in readinto
    return self._sock.recv_into(b)
  File "/opt/spark/python/lib/pyspark.zip/pyspark/context.py", line 381, in signal_handler
    self.cancelAllJobs()
  File "/opt/spark/python/lib/pyspark.zip/pyspark/context.py", line 2446, in cancelAllJobs
    self._jsc.sc().cancelAllJobs()
  File "/opt/spark/python/lib/py4j-0.10.9.7-src.zip/py4j/java_gateway.py", line 1322, in __call__
    return_value = get_return_value(
  File "/opt/spark/python/lib/pyspark.zip/pyspark/errors/exceptions/captured.py", line 179, in deco
    return f(*a, **kw)
  File "/opt/spark/python/lib/py4j-0.10.9.7-src.zip/py4j/protocol.py", line 334, in get_return_value
    raise Py4JError(
py4j.protocol.Py4JError: An error occurred while calling o17.sc

During handling of the above exception, another exception occurred:

Traceback (most recent call last):
  File "/opt/spark/python/lib/py4j-0.10.9.7-src.zip/py4j/java_gateway.py", line 1038, in send_command
    response = connection.send_command(command)
  File "/opt/spark/python/lib/py4j-0.10.9.7-src.zip/py4j/clientserver.py", line 539, in send_command
    raise Py4JNetworkError(
py4j.protocol.Py4JNetworkError: Error while sending or receiving
Traceback (most recent call last):
  File "/home/pes2ug22cs311/distributed-log-emoji-stream/consumer.py", line 114, in <module>
    query.awaitTermination()
  File "/opt/spark/python/lib/pyspark.zip/pyspark/sql/streaming/query.py", line 221, in awaitTermination
  File "/opt/spark/python/lib/py4j-0.10.9.7-src.zip/py4j/java_gateway.py", line 1322, in __call__
  File "/opt/spark/python/lib/pyspark.zip/pyspark/errors/exceptions/captured.py", line 179, in deco
  File "/opt/spark/python/lib/py4j-0.10.9.7-src.zip/py4j/protocol.py", line 334, in get_return_value
py4j.protocol.Py4JError: An error occurred while calling o77.awaitTermination
